Workbook

Sheet Missing Photos
A1: Company | B1: Product | C1: Pack | D1: Composition | E1: PTS | F1: MRP | G1: Expected filename | H1: Priority | I1: Shot? | J1: Possible duplicate of
A2: Alkem - Futura / NEXX | B2: ALCEFF NOVO 250MG CAPSULES (10'S) | C2: 10's | D2: Cephalexin 250 mg | E2: 29.05 | F2: 84 | G2: alceff novo 250mg capsules (10's).jpg | J2: ALCEFF NOVO 500MG CAPSULES (10'S)
A3: Alkem - Futura / NEXX | B3: ALCEFF NOVO 500MG CAPSULES (10'S) | C3: 10's | D3: Cephalexin 500 mg | E3: 52 | F3: 181 | G3: alceff novo 500mg capsules (10's).jpg | J3: ALCEFF NOVO 250MG CAPSULES (10'S)
A4: Alkem - Futura / NEXX | B4: ALCIFLOX 250MG TABLETS (10S) | C4: 10’s | D4: Ciprofloxacin 250 mg | E4: 11.45 | F4: 24.53 | G4: alciflox 250mg tablets (10s).jpg | J4: ALCIFLOX 500MG TABLETS (10S)
A5: Alkem - Futura / NEXX | B5: ALCIFLOX D (EYE/EAR DROPS) (10ML) | C5: 10 ml | D5: Ciprofloxacin 0.3% w/v + Dexamethasone 0.1% w/v | E5: 12.5 | F5: 53 | G5: alciflox d (eyeear drops) (10ml).jpg
A6: Alkem - Futura / NEXX | B6: ALCIFLOX-TZ TABLETS (10'S) | C6: 10's | D6: Ciprofloxacin 500 mg + Tinidazole 600 mg | E6: 33.35 | F6: 93 | G6: alciflox-tz tablets (10's).jpg
A7: Alkem - Futura / NEXX | B7: ALDIGESIC P TABLETS (ALU-ALU) (10'S) | C7: 10's | D7: Aceclofenac 100 mg + Paracetamol 325 mg | E7: 15.9 | F7: 99 | G7: aldigesic p tablets (alu-alu) (10's).jpg
A8: Alkem - Futura / NEXX | B8: ALDRYL + COUGH SYRUP (100ML) | C8: 100 ML | D8: Diphenhydramine HCl 15 mg + Ammonium Chloride 120 mg + Sodium Citrate 60 mg + Menthol 1 mg / 5 ml | E8: 10.95 | F8: 114 | G8: aldryl + cough syrup (100ml).jpg | J8: ALDRYL + COUGH SYRUP (60ML)
A9: Alkem - Futura / NEXX | B9: ALGAT EYE DROPS (10ML) | C9: 10 ml | D9: Gatifloxacin 0.3% w/v | E9: 10.05 | F9: 62 | G9: algat eye drops (10ml).jpg
A10: Alkem - Futura / NEXX | B10: ALKEM PARA 500 TABLETS (10'S) | C10: 10'S | D10: Paracetamol 500 mg | E10: 4.95 | F10: 10.04 | G10: alkem para 500 tablets (10's).jpg | J10: ALKEM PARA 500 TABLETS (15'S)
A11: Alkem - Futura / NEXX | B11: ALKEM'S AMOXICILLINE LOOSE | C11: 1000'S | D11: Amoxicillin 250 mg | E11: 1510.55 | F11: 2087 | G11: alkem's amoxicilline loose.jpg
A12: Alkem - Futura / NEXX | B12: ALKEM'S KETOROLAC INJECTION | C12: 1ml | D12: Ketorolac Tromethamine 30 mg /ml | E12: 5.3 | F12: 36 | G12: alkem's ketorolac injection.jpg
A13: Alkem - Futura / NEXX | B13: ALKEM'S PIROXICAM INJECTION (2ML) | C13: 2 ml | D13: Piroxicam 20 mg / ml | E13: 6.95 | F13: 31 | G13: alkem's piroxicam injection (2ml).jpg
A14: Alkem - Futura / NEXX | B14: ALKEMERO 0.5 Gm INJECTION (VIAL) | C14: 10 ml | D14: Meropenem 500mg | E14: 63.55 | F14: 671.63 | G14: alkemero 0.5 gm injection (vial).jpg | J14: ALKEMERO 1 Gm INJECTION (VIAL)
A15: Alkem - Futura / NEXX | B15: ALKOF + COUGH SYRUP (100ML) | C15: 100ml | D15: Terbutaline Sulphate1.25 mg + Guaiphenesin 50 mg + Bromhexine HCl 2 mg + Menthol 0.5 mg / 5 ml | E15: 16.7 | F15: 66 | G15: alkof + cough syrup (100ml).jpg | J15: ALKOF + COUGH SYRUP (60ML)
A16: Alkem - Futura / NEXX | B16: ALKOF + COUGH SYRUP (60ML) | C16: 60ml | D16: Terbutaline Sulphate1.25 mg + Guaiphenesin 50 mg + Bromhexine HCl 2 mg + Menthol 0.5 mg / 5 ml | E16: 11.25 | F16: 40 | G16: alkof + cough syrup (60ml).jpg | J16: ALKOF + COUGH SYRUP (100ML)
A17: Alkem - Futura / NEXX | B17: ALKOF DX PLUS COUGH SYP 100 ML | C17: 100 ML | D17: Chlorpheniramine Maleate 4 mg + Dextromethorphan HBr 10 mg / 5 ml | E17: 21.6 | F17: 86 | G17: alkof dx plus cough syp 100 ml.jpg | J17: ALKOF DX PLUS COUGH SYP 60 ML
A18: Alkem - Futura / NEXX | B18: ALKOF DX PLUS COUGH SYP 60 ML | C18: 60 ML | D18: Chlorpheniramine Maleate 4 mg + Dextromethorphan HBr 10 mg / 5 ml | E18: 11.25 | F18: 58 | G18: alkof dx plus cough syp 60 ml.jpg | J18: ALKOF DX PLUS COUGH SYP 100 ML
A19: Alkem - Futura / NEXX | B19: ALKOF LS SYRUP (100ML) | C19: 100 ml | D19: Ambroxol HCl 15 mg + Levosalbutamol 0.5 mg + Guaiphenesin 50 mg + Menthol 0.5 mg /5 ml | E19: 21 | F19: 118 | G19: alkof ls syrup (100ml).jpg
A20: Alkem - Futura / NEXX | B20: ALKOF LS+ COUGH SYRUP (100 ML) | C20: 100 ml | D20: Ambroxol HCl 30 mg + Levosalbutamol 1 mg + Guaiphenesin 50 mg /5 ml | E20: 24.55 | F20: 0 | G20: alkof ls+ cough syrup (100 ml).jpg
A21: Alkem - Futura / NEXX | B21: ALMEFKEM - DS SUSPENSION | C21: 60 ML | D21: Mefenamic Acid 100 mg / 5 ml | E21: 13.7 | F21: 0 | G21: almefkem - ds suspension.jpg
A22: Alkem - Futura / NEXX | B22: ALMEFKEM 250 DT TABLETS (10'S) | C22: 10's | D22: Mefenamic Acid 250 mg | F22: 0 | G22: almefkem 250 dt tablets (10's).jpg
A23: Alkem - Futura / NEXX | B23: ALMEFKEM 500MG TABLETS (10'S) | C23: 10's | D23: Mefenamic Acid 500 mg | F23: 0 | G23: almefkem 500mg tablets (10's).jpg
A24: Alkem - Futura / NEXX | B24: ALMEFKEM SPAS (10S) | C24: 10's | D24: Mefenamic Acid 250 mg + Dicyclomine HCl 10 mg | E24: 12.7 | F24: 63 | G24: almefkem spas (10s).jpg
A25: Alkem - Futura / NEXX | B25: ALMOX 500MG CAPSULES (15'S) (ORANGE) | C25: 15's | D25: Amoxicillin 500 mg | E25: 45.2 | F25: 0 | G25: almox 500mg capsules (15's) (orange).jpg
A26: Alkem - Futura / NEXX | B26: ALMOX CAPSULES 250 MG (15'S) RED & WHITE | C26: 15's | D26: Amoxicillin 500 mg | E26: 22.55 | F26: 40.99 | G26: almox capsules 250 mg (15's) red & white.jpg
A27: Alkem - Futura / NEXX | B27: ALMOX DRY SYRUP 125MG/5ML (30ML) | C27: 30ml | D27: Amoxicillin 125 mg / 5 ml | E27: 14.95 | F27: 30.27 | G27: almox dry syrup 125mg5ml (30ml).jpg
A28: Alkem - Futura / NEXX | B28: ALMOX DRY SYRUP 125MG/5ML (60ML W.C.) | C28: 60ml | D28: Amoxicillin 125 mg / 5 ml | E28: 24.3 | F28: 61.66 | G28: almox dry syrup 125mg5ml (60ml w.c.).jpg
A29: Alkem - Futura / NEXX | B29: ALMOX DT 125 MG TABLETS [ 15S ] | C29: 15's | D29: Amoxicillin 125 mg Dispersible Tablets | E29: 22.1 | F29: 80 | G29: almox dt 125 mg tablets [ 15s ].jpg | J29: ALMOX DT 250 MG TABLETS (15S)
A30: Alkem - Futura / NEXX | B30: ALMOX-CV 625MG TABLETS (6'S) | C30: 6’s | D30: Amoxicillin 500 mg + Clavulanic Acid 125 MG | E30: 44.35 | F30: 122.91 | G30: almox-cv 625mg tablets (6's).jpg | J30: ALMOX-CV 625MG TABLETS (10'S)
A31: Alkem - Futura / NEXX | B31: ALSIUM 500 TABLETS | C31: 15' s | D31: Calcium Carbonate 1.25 gm (from organic source of Oyster shell) eq. to elemental Calcium 500 mg + Vitamin D3 500 IU | E31: 13.8 | F31: 207 | G31: alsium 500 tablets.jpg
A32: Alkem - Futura / NEXX | B32: AMIJECT 100MG INJECTION (VIAL) | C32: Vial | D32: Amikacin 100 mg / 2 ml | E32: 12.05 | F32: 31 | G32: amiject 100mg injection (vial).jpg | J32: AMIJECT 500MG INJECTION (VIAL)
A33: Alkem - Futura / NEXX | B33: AMIJECT 250MG INJECTION (VIAL) | C33: Vial | D33: Amikacin 250 mg / 2 ml | E33: 20.1 | F33: 37 | G33: amiject 250mg injection (vial).jpg | J33: AMIJECT 500MG INJECTION (VIAL)
A34: Alkem - Futura / NEXX | B34: AMIJECT 500MG INJECTION (VIAL) | C34: Vial | D34: Amikacin 500 mg / 2 ml | E34: 21.5 | F34: 113.76 | G34: amiject 500mg injection (vial).jpg | J34: AMIJECT 100MG INJECTION (VIAL) | AMIJECT 250MG INJECTION (VIAL)
A35: Alkem - Futura / NEXX | B35: AZIKEM - XL SUSPENSION 100 mg (30 ML) | C35: 30ml | D35: Azithromycin 100 mg / 5 ml | E35: 30.75 | F35: 76 | G35: azikem - xl suspension 100 mg (30 ml).jpg | J35: AZIKEM - XL SUSPENSION 200 mg (30 ML)
A36: Alkem - Futura / NEXX | B36: AZIKEM - XL SUSPENSION 200 mg (30 ML) | C36: 30ml | D36: Azithromycin 200 mg/ 5 ml | E36: 46.55 | F36: 114.52 | G36: azikem - xl suspension 200 mg (30 ml).jpg | J36: AZIKEM - XL SUSPENSION 100 mg (30 ML)
A37: Alkem - Futura / NEXX | B37: AZIKEM 250 TABLETS [ 10'S ] | C37: 10'S | D37: Azithromycin 250 mg | E37: 51.35 | F37: 0 | G37: azikem 250 tablets [ 10's ].jpg | J37: AZIKEM 250 TABLETS [ 6'S ]
A38: Alkem - Futura / NEXX | B38: AZIKEM 500 TAB (5'S) | C38: 5'S | D38: Azithromycin 500 mg | E38: 51.35 | F38: 131.97 | G38: azikem 500 tab (5's).jpg
A39: Alkem - Futura / NEXX | B39: BILAKEM MONT SYP | C39: 60 ML | D39: Bilastine 10mg + Montelukast 4mg/ 5 ml | E39: 29.85 | F39: 137 | G39: bilakem mont syp.jpg
A40: Alkem - Futura / NEXX | B40: BILAKEM MONT TABLETS | C40: 10's | D40: Bilastine 20mg + Montelukast 10mg | E40: 27.9 | F40: 180 | G40: bilakem mont tablets.jpg
...

Sheet Summary
A1: Company | B1: Missing photos | C1: Total SKUs | D1: % covered
A2: Alkem - Futura / NEXX | B2: =COUNTIF('Missing Photos'!$A:$A,$A2) | C2: 261 | D2: =IFERROR(1-B2/C2,0)
A3: Alkem - Maxxio | B3: =COUNTIF('Missing Photos'!$A:$A,$A3) | C3: 215 | D3: =IFERROR(1-B3/C3,0)
A4: Alkem - Novokem | B4: =COUNTIF('Missing Photos'!$A:$A,$A4) | C4: 203 | D4: =IFERROR(1-B4/C4,0)
A5: Alkem Healthcare | B5: =COUNTIF('Missing Photos'!$A:$A,$A5) | C5: 155 | D5: =IFERROR(1-B5/C5,0)
A6: Lupin | B6: =COUNTIF('Missing Photos'!$A:$A,$A6) | C6: 277 | D6: =IFERROR(1-B6/C6,0)
A7: RANBAXY | B7: =COUNTIF('Missing Photos'!$A:$A,$A7) | C7: 130 | D7: =IFERROR(1-B7/C7,0)
A8: Shivayur | B8: =COUNTIF('Missing Photos'!$A:$A,$A8) | C8: 25 | D8: =IFERROR(1-B8/C8,0)
A9: Silver-cross | B9: =COUNTIF('Missing Photos'!$A:$A,$A9) | C9: 6 | D9: =IFERROR(1-B9/C9,0)
A10: Torque | B10: =COUNTIF('Missing Photos'!$A:$A,$A10) | C10: 304 | D10: =IFERROR(1-B10/C10,0)
A11: TOTAL | B11: =SUM(B2:B10) | C11: =SUM(C2:C10) | D11: =IFERROR(1-B11/C11,0)
A13: Legend
A14: Yellow columns (Priority, Shot?) are for you to fill in.
A15: Cream rows = product name near-matches another row in Master_File (223 rows). Likely a duplicate/typo — fix the Excel before shooting.
A16: Expected filename = save the photo in Photos/ under exactly this name.
